['LuCaP_173', 'LuCaP_167', 'LuCaP_93', 'LuCaP_81', 'LuCaP_70', 'LuCaP_189', 'LuCaP_78', 'LuCaP_208', 'LuCaP_86', 'LuCaP_141', 'LuCaP_58', 'LuCaP_77', 'LuCaP_170', 'LuCaP_145', 'LuCaP_49', 'LuCaP_136', 'LuCaP_92']

[INFO] Loading intervals for LuCaP_173
Parsl version: 1.3.0-dev
[INFO] Starting on batch 1 of 27
[INFO] Creating futures for inputs:   0%|          | 0/1000 [00:00<?, ?it/s]Traceback (most recent call last):
  File "/lus/theta-fs0/projects/covid-ct/imlab/users/temi/projects/TFXcan/enformer-predict/scripts/enformer-predict-personalized.py", line 135, in <module>
    main()
  File "/lus/theta-fs0/projects/covid-ct/imlab/users/temi/projects/TFXcan/enformer-predict/scripts/enformer-predict-personalized.py", line 118, in main
    sequence_list = [s.result() for s in sequence_list_appfutures]
  File "/lus/theta-fs0/projects/covid-ct/imlab/users/temi/projects/TFXcan/enformer-predict/scripts/enformer-predict-personalized.py", line 118, in <listcomp>
    sequence_list = [s.result() for s in sequence_list_appfutures]
  File "/home/temi/miniconda3/envs/dl-tools/lib/python3.10/concurrent/futures/_base.py", line 458, in result
    return self.__get_result()
  File "/home/temi/miniconda3/envs/dl-tools/lib/python3.10/concurrent/futures/_base.py", line 403, in __get_result
    raise self._exception
  File "/home/temi/miniconda3/envs/dl-tools/lib/python3.10/site-packages/parsl/dataflow/dflow.py", line 288, in handle_exec_update
    res = self._unwrap_remote_exception_wrapper(future)
  File "/home/temi/miniconda3/envs/dl-tools/lib/python3.10/site-packages/parsl/dataflow/dflow.py", line 483, in _unwrap_remote_exception_wrapper
    result.reraise()
  File "/home/temi/miniconda3/envs/dl-tools/lib/python3.10/site-packages/parsl/app/errors.py", line 137, in reraise
    reraise(t, v, v.__traceback__)
  File "/home/temi/miniconda3/envs/dl-tools/lib/python3.10/site-packages/six.py", line 719, in reraise
    raise value
  File "/home/temi/miniconda3/envs/dl-tools/lib/python3.10/site-packages/parsl/app/errors.py", line 176, in wrapper
    except Exception:
  File "<string>", line 236, in create_input
  File "/home/temi/miniconda3/envs/dl-tools/lib/python3.10/site-packages/parsl/app/python.py", line 68, in __call__
    dfk = DataFlowKernelLoader.dfk()
  File "/home/temi/miniconda3/envs/dl-tools/lib/python3.10/site-packages/parsl/dataflow/dflow.py", line 1348, in dfk
    raise RuntimeError('Must first load config')
RuntimeError: Must first load config
